Workbook
Name IntervaloNomeado1: Os!$1:$1
Name IntervaloNomeado2: Os!$B$1:$AF$1

Sheet Os
A1: IdOs | B1: Contrato | C1: Obra | D1: Protocolo | E1: Produto | F1: Entrante | G1: Prev. Exec. | H1: Observacoes | I1: Conclusao | J1: Descricao | K1: Cidade | L1: ValorServico | M1: StatusOperacao | N1: RespCliente | O1: MedicaoConsolidada | P1: ValorPago | Q1: StatusMedicao | R1: StatusFinal | S1: ValorTercerizacao | T1: NPedidodeCompra | U1: Equipe | V1: NomeEquipe | W1: Lançamento | X1: CaboLancado? | Y1: InfraRealizada? | Z1: ProblemaEncontradoReparo | AA1: CausaRaiz(Reparo) | AB1: AcaoCorretiva(Reparo) | AC1: MaterialAplicado | AD1: Projeto | AE1: SituacaoAtual | AF1: Tempo | AG1: NumNF | AH1: MaterialAplicado? | AI1: Data AGRUP_Entrante | AJ1: Data AGRUP_Conclusão | AK1: Status Prazo | AL1: Ard | AM1: MotivoPerda | AN1: ResponsavelPerda | AO1: UF | AP1: POP | AQ1: Mes | AR1: Cenario | AS1: FacilidadesPlanejadas | AT1: CaixasPlanejadas | AU1: LançamentoPlanejado | AV1: TipoOs
A2: a1 | D2: 34907680 | F2: 45805 | G2: 45838 | I2: 45814 | L2: 10558.35 | M2: Concluído | Q2: NF Recebida | R2: Concluido | AF2: =IF(M2="Concluido",I2-F2,IF(M2="Cancelado",0,TODAY()-F2)) -> 197 | AO2: RN | AP2: NTL16 | AQ2: JUN-25 | AR2: C1 | AS2: 648 | AT2: 81 | AV2: Alivio Proativo
A3: a2 | D3: 35160533 | F3: 45818 | G3: 45838 | I3: 45828 | L3: 7885.35 | M3: Concluído | Q3: NF Recebida | R3: Concluido | AF3: =IF(M3="Concluido",I3-F3,IF(M3="Cancelado",0,TODAY()-F3)) -> 184 | AO3: RN | AP3: NTL17 | AQ3: JUN-25 | AR3: C1 | AS3: 504 | AT3: 63 | AV3: Alivio Proativo
A4: a3 | D4: 35213284 | F4: 45824 | G4: 45868 | I4: 45833.635 | L4: 8152.65 | M4: Concluído | Q4: NF Recebida | R4: Concluido | AF4: =IF(M4="Concluido",I4-F4,IF(M4="Cancelado",0,TODAY()-F4)) -> 178 | AO4: RN | AP4: NTL14 | AQ4: JUN-25 | AR4: C1 | AS4: 584 | AT4: 73 | AV4: Alivio Proativo
A5: a4 | D5: 35217090 | F5: 45824 | G5: 45868 | I5: 45829 | L5: 4276.8 | M5: Concluído | Q5: NF Recebida | R5: Concluido | AF5: =IF(M5="Concluido",I5-F5,IF(M5="Cancelado",0,TODAY()-F5)) -> 178 | AO5: RN | AP5: STO01 | AQ5: JUN-25 | AR5: C1 | AS5: 264 | AT5: 33 | AV5: Alivio Proativo
A6: a5 | D6: 35126349 | F6: 45818 | G6: 45838 | I6: 45821 | L6: 12563.1 | M6: Concluído | Q6: NF Recebida | R6: Concluido | AF6: =IF(M6="Concluido",I6-F6,IF(M6="Cancelado",0,TODAY()-F6)) -> 184 | AO6: RN | AP6: NTL15 | AQ6: JUN-25 | AR6: C1 | AS6: 800 | AT6: 100 | AV6: Alivio Proativo
A7: a6 | D7: 35232967 | F7: 45825 | G7: 45831 | I7: 45826 | L7: 514.8 | M7: Concluído | Q7: NF Recebida | R7: Concluido | AF7: =IF(M7="Concluido",I7-F7,IF(M7="Cancelado",0,TODAY()-F7)) -> 177 | AO7: CE | AP7: FLA05 | AQ7: JUN-25 | AR7: C3 | AS7: 8 | AT7: 1 | AV7: Alivio Proativo
A8: a7 | D8: 35240227 | F8: 45826 | G8: 45838 | I8: 45826 | L8: 514.8 | M8: Concluído | Q8: NF Recebida | R8: Concluido | AF8: =IF(M8="Concluido",I8-F8,IF(M8="Cancelado",0,TODAY()-F8)) -> 176 | AO8: RN | AP8: NTL06 | AQ8: JUN-25 | AR8: REATIVO | AS8: 8 | AT8: 1 | AV8: Alivio Reativo
A9: a8 | D9: 35237804 | F9: 45825 | G9: 45839 | H9: CABOS JÁ LANÇADOS, AGURADANDO LIBERAÇÃO PRA PODER FINALIZAR ATIVIDADE | M9: Cancelado | R9: Declinado Sem Acesso | AF9: =IF(M9="Concluido",I9-F9,IF(M9="Cancelado",0,TODAY()-F9)) -> 0 | AO9: PB | AP9: JPA00 | AQ9: JUN-25 | AR9: MDU | AS9: 8 | AT9: 1 | AV9: MDU
A10: a9 | D10: 35236516 | F10: 45825 | G10: 45838 | I10: 45833.596 | L10: 1564.2 | M10: Concluído | Q10: NF Recebida | R10: Concluido | AF10: =IF(M10="Concluido",I10-F10,IF(M10="Cancelado",0,TODAY()-F10)) -> 177 | AO10: PB | AP10: JPA00 | AQ10: JUN-25 | AR10: MDU | AS10: 8 | AT10: 1 | AV10: MDU
A11: a10 | D11: 35239625 | F11: 45826 | G11: 45839 | I11: 45835.453 | L11: 1940.4 | M11: Concluído | Q11: NF Recebida | R11: Concluido | AF11: =IF(M11="Concluido",I11-F11,IF(M11="Cancelado",0,TODAY()-F11)) -> 176 | AO11: PB | AP11: JPA00 | AQ11: JUN-25 | AR11: MDU | AS11: 16 | AT11: 2 | AV11: MDU
A12: a11 | D12: 35240907 | F12: 45826 | G12: 45832 | M12: Cancelado | R12: Declinado Sem Acesso | AF12: =IF(M12="Concluido",I12-F12,IF(M12="Cancelado",0,TODAY()-F12)) -> 0 | AO12: CE | AP12: FLA09 | AQ12: JUN-25 | AR12: REATIVO | AS12: 8 | AT12: 1 | AV12: Alivio Reativo
A13: a12 | D13: 35240874 | F13: 45826 | G13: 45838 | I13: 45833.377 | L13: 1544.4 | M13: Concluído | Q13: NF Recebida | R13: Concluido | AF13: =IF(M13="Concluido",I13-F13,IF(M13="Cancelado",0,TODAY()-F13)) -> 176 | AO13: CE | AP13: FLA12 | AQ13: JUN-25 | AR13: REATIVO | AS13: 24 | AT13: 3 | AV13: Alivio Reativo
A14: a13 | D14: 35232463 | F14: 45825 | G14: 45838 | M14: Cancelado | R14: Inviabilidade Técnica | AF14: =IF(M14="Concluido",I14-F14,IF(M14="Cancelado",0,TODAY()-F14)) -> 0 | AO14: CE | AP14: FLA22 | AQ14: JUN-25 | AR14: MDU | AS14: 64 | AT14: 8 | AV14: MDU
A15: a14 | D15: 35242081 | F15: 45826 | G15: 45838 | I15: 45826 | L15: 3496.4 | M15: Concluído | Q15: NF Recebida | R15: Concluido | AF15: =IF(M15="Concluido",I15-F15,IF(M15="Cancelado",0,TODAY()-F15)) -> 176 | AO15: CE | AP15: MCW02 | AQ15: JUN-25 | AR15: B2B | AS15: 8 | AT15: 1 | AV15: B2B
A16: a15 | D16: 35201709 | F16: 45824 | G16: 45841 | I16: 45831 | L16: 5712.09 | M16: Concluído | Q16: NF Recebida | R16: Concluido | AF16: =IF(M16="Concluido",I16-F16,IF(M16="Cancelado",0,TODAY()-F16)) -> 178 | AO16: CE | AP16: FLA16 | AQ16: JUN-25 | AR16: LPU | AS16: 0 | AT16: 0 | AV16: Const. de Redes
A17: a16 | D17: 35280769 | F17: 45831 | G17: 45868 | I17: 45839.349 | L17: 16038 | M17: Concluído | Q17: NF Recebida | R17: Concluido | AF17: =IF(M17="Concluido",I17-F17,IF(M17="Cancelado",0,TODAY()-F17)) -> 171 | AO17: CE | AP17: FLA20 | AQ17: JUN-25 | AR17: C1 | AS17: 1000 | AT17: 125 | AV17: Alivio Proativo
A18: a17 | D18: 35254508 | F18: 45828 | G18: 45840 | M18: Cancelado | R18: Inviabilidade Técnica | AF18: =IF(M18="Concluido",I18-F18,IF(M18="Cancelado",0,TODAY()-F18)) -> 0 | AO18: CE | AP18: FLA15 | AQ18: JUN-25 | AR18: MDU | AS18: 64 | AT18: 8 | AV18: MDU
A19: a18 | D19: 35256292 | F19: 45828 | G19: 45840 | M19: Cancelado | R19: Inviabilidade Técnica | AF19: =IF(M19="Concluido",I19-F19,IF(M19="Cancelado",0,TODAY()-F19)) -> 0 | AO19: CE | AP19: ESB01 | AQ19: JUN-25 | AR19: MDU | AS19: 40 | AT19: 5 | AV19: MDU
A20: a19 | D20: 35277733 | F20: 45828 | G20: 45835 | I20: 45833.371 | L20: 4849.98 | M20: Concluído | Q20: NF Recebida | R20: Concluido | AF20: =IF(M20="Concluido",I20-F20,IF(M20="Cancelado",0,TODAY()-F20)) -> 174 | AO20: PB | AP20: JPA00 | AQ20: JUN-25 | AR20: LPU | AS20: 0 | AT20: 0 | AV20: Alivio Proativo
A21: a20 | D21: 35278156 | F21: 45828 | G21: 45835 | H21: 2500m LANÇAMENTO | I21: 45835.709 | L21: 8275 | M21: Concluído | Q21: NF Recebida | R21: Concluido | AF21: =IF(M21="Concluido",I21-F21,IF(M21="Cancelado",0,TODAY()-F21)) -> 174 | AO21: RN | AP21: GOH01 | AQ21: JUN-25 | AR21: LPU | AS21: 0 | AT21: 0 | AV21: Alivio Proativo
A22: a21 | D22: 35281452 | F22: 45831 | G22: 45842 | M22: Cancelado | R22: Inviabilidade Técnica | AF22: =IF(M22="Concluido",I22-F22,IF(M22="Cancelado",0,TODAY()-F22)) -> 0 | AO22: RN | AP22: NTL17 | AQ22: JUN-25 | AR22: MDU | AS22: 16 | AT22: 2 | AV22: MDU
A23: a22 | D23: 35255930 | F23: 45828 | G23: 45840 | M23: Cancelado | R23: Inviabilidade Técnica | AF23: =IF(M23="Concluido",I23-F23,IF(M23="Cancelado",0,TODAY()-F23)) -> 0 | AO23: RN | AP23: NTL17 | AQ23: JUN-25 | AR23: MDU | AS23: 32 | AT23: 4 | AV23: MDU
A24: a23 | D24: 35255165 | F24: 45828 | G24: 45838 | I24: 45840.488 | L24: 7167.6 | M24: Concluído | Q24: NF Recebida | R24: Concluido | AF24: =IF(M24="Concluido",I24-F24,IF(M24="Cancelado",0,TODAY()-F24)) -> 174 | AO24: RN | AP24: NTL01 | AQ24: JUN-25 | AR24: C4 | AS24: 64 | AT24: 8 | AV24: Alivio Proativo
A25: a24 | D25: 35308809 | F25: 45832 | G25: 45845 | I25: 45834.632 | L25: 1029.6 | M25: Concluído | Q25: NF Recebida | R25: Concluido | AF25: =IF(M25="Concluido",I25-F25,IF(M25="Cancelado",0,TODAY()-F25)) -> 170 | AO25: RN | AP25: NTL09 | AQ25: JUN-25 | AR25: REATIVO | AS25: 16 | AT25: 2 | AV25: Alivio Reativo
A26: a25 | D26: 35079904 | F26: 45817 | G26: 45838 | I26: 45821 | L26: 14835.15 | M26: Concluído | Q26: NF Recebida | R26: Concluido | AF26: =IF(M26="Concluido",I26-F26,IF(M26="Cancelado",0,TODAY()-F26)) -> 185 | AO26: RN | AP26: NTL13 | AQ26: JUN-25 | AR26: C1 | AS26: 1000 | AT26: 125 | AV26: Alivio Proativo
A27: a26 | D27: 34911211 | F27: 45805 | G27: 45838 | I27: 45814 | L27: 10424.7 | M27: Concluído | Q27: NF Recebida | R27: Concluido | AF27: =IF(M27="Concluido",I27-F27,IF(M27="Cancelado",0,TODAY()-F27)) -> 197 | AO27: RN | AP27: NTL18 | AQ27: JUN-25 | AR27: C1 | AS27: 624 | AT27: 78 | AV27: Alivio Proativo
A28: a27 | D28: 34747591 | F28: 45796 | G28: 45807 | I28: 45814 | L28: 9444.6 | M28: Concluído | Q28: NF Recebida | R28: Concluido | AF28: =IF(M28="Concluido",I28-F28,IF(M28="Cancelado",0,TODAY()-F28)) -> 206 | AO28: CE | AP28: FLA08 | AQ28: JUN-25 | AR28: MDU | AS28: 120 | AT28: 15 | AV28: MDU
A29: a28 | D29: 34710933 | F29: 45792 | G29: 45805 | I29: 45812 | L29: 10216.8 | M29: Concluído | Q29: NF Recebida | R29: Concluido | AF29: =IF(M29="Concluido",I29-F29,IF(M29="Cancelado",0,TODAY()-F29)) -> 210 | AO29: CE | AP29: FLA09 | AQ29: JUN-25 | AR29: MDU | AS29: 192 | AT29: 24 | AV29: MDU
A30: a29 | D30: 35183696 | F30: 45819 | G30: 45832 | I30: 45821 | L30: 1940.4 | M30: Concluído | Q30: NF Recebida | R30: Concluido | AF30: =IF(M30="Concluido",I30-F30,IF(M30="Cancelado",0,TODAY()-F30)) -> 183 | AO30: CE | AP30: FLA14 | AQ30: JUN-25 | AR30: MDU | AS30: 16 | AT30: 2 | AV30: MDU
A31: a30 | D31: 34881184 | F31: 45805 | G31: 45817 | I31: 45819 | L31: 9365.4 | M31: Concluído | Q31: NF Recebida | R31: Concluido | AF31: =IF(M31="Concluido",I31-F31,IF(M31="Cancelado",0,TODAY()-F31)) -> 197 | AO31: CE | AP31: FLA12 | AQ31: JUN-25 | AR31: MDU | AS31: 160 | AT31: 20 | AV31: MDU
A32: a31 | D32: 35009048 | F32: 45810 | G32: 45821 | I32: 45814 | L32: 1940.4 | M32: Concluído | Q32: NF Recebida | R32: Concluido | AF32: =IF(M32="Concluido",I32-F32,IF(M32="Cancelado",0,TODAY()-F32)) -> 192 | AO32: CE | AP32: FLA32 | AQ32: JUN-25 | AR32: MDU | AS32: 16 | AT32: 2 | AV32: MDU
A33: a32 | D33: 34871192 | F33: 45805 | G33: 45817 | I33: 45819 | L33: 3069 | M33: Concluído | Q33: NF Recebida | R33: Concluido | AF33: =IF(M33="Concluido",I33-F33,IF(M33="Cancelado",0,TODAY()-F33)) -> 197 | AO33: CE | AP33: FLA09 | AQ33: JUN-25 | AR33: MDU | AS33: 40 | AT33: 5 | AV33: MDU
A34: a33 | D34: 34997884 | F34: 45810 | G34: 45814 | I34: 45811 | L34: 514.8 | M34: Concluído | Q34: NF Recebida | R34: Concluido | AF34: =IF(M34="Concluido",I34-F34,IF(M34="Cancelado",0,TODAY()-F34)) -> 192 | AO34: CE | AP34: FLA19 | AQ34: JUN-25 | AR34: REATIVO | AS34: 8 | AT34: 1 | AV34: Alivio Reativo
A35: a34 | D35: 35216936 | F35: 45824 | G35: 45868 | I35: 45825 | L35: 1069.2 | M35: Concluído | Q35: NF Recebida | R35: Concluido | AF35: =IF(M35="Concluido",I35-F35,IF(M35="Cancelado",0,TODAY()-F35)) -> 178 | AO35: CE | AP35: FLA21 | AQ35: JUN-25 | AR35: C1 | AS35: 88 | AT35: 11 | AV35: Alivio Proativo
... A43: a42 | D43: 35234503 | F43: 45825 | G43: 45831 | I43: 45826 | L43: 900.9 | M43: Concluído | Q43: NF Recebida | R43: Concluido | AF43: =IF(M43="Concluido",I43-F43,IF(M43="Cancelado",0,TODAY()-F43)) -> 177 | AO43: CE | AP43: FLA27 | AQ43: JUN-25 | AR43: C1 | AS43: 16 | AT43: 1 | AV43: Alivio Proativo
A44: a43 | D44: 35126884 | F44: 45818 | G44: 45824 | I44: 45824 | L44: 15976.51 | M44: Concluído | Q44: NF Recebida | R44: Concluido | AF44: =IF(M44="Concluido",I44-F44,IF(M44="Cancelado",0,TODAY()-F44)) -> 184 | AO44: CE | AQ44: JUN-25 | AR44: LPU | AS44: 1 | AT44: 1 | AV44: B2B
A45: 9dba3ce2 | D45: 35372414 | F45: 45833 | G45: 45840 | I45: 45835.658 | L45: 346.5 | M45: Concluído | Q45: NF Recebida | R45: Concluido | AF45: =IF(M45="Concluido",I45-F45,IF(M45="Cancelado",0,TODAY()-F45)) -> 169 | AO45: CE | AP45: FLA05 | AQ45: JUN-25 | AR45: C2 | AS45: 8 | AT45: 1 | AV45: Alivio Reativo
A46: a44 | D46: 35336923 | F46: 45833 | G46: 45844 | H46: Semana 01/JUL-25 | I46: 45849.699 | L46: 16572.6 | M46: Concluído | Q46: NF Recebida | R46: Concluido | AF46: =IF(M46="Concluido",I46-F46,IF(M46="Cancelado",0,TODAY()-F46)) -> 169 | AO46: RN | AP46: NTL21 | AQ46: JUL-25 | AR46: C1 | AS46: 1000 | AT46: 125 | AV46: Alivio Proativo
A47: a45 | D47: 35338033 | F47: 45833 | G47: 45844 | H47: Semana 01/JUL-25 | I47: 45846.493 | L47: 9890.1 | M47: Concluído | Q47: NF Recebida | R47: Concluido | AF47: =IF(M47="Concluido",I47-F47,IF(M47="Cancelado",0,TODAY()-F47)) -> 169 | AO47: RN | AP47: CGM01 | AQ47: JUL-25 | AR47: C1 | AS47: 600 | AT47: 75 | AV47: Alivio Proativo
...

Sheet CaixaAlares
A1: IdCaixa | B1: Projeto | C1: Pop | D1: Cidade | E1: UF | F1: Chassi | G1: Placa | H1: OLT | I1: Cto | J1: Cenario | K1: Bairro | L1: Endereco | M1: Lat | N1: Long | O1: OS | P1: Status | Q1: Potência | R1: Valor | S1: Equipe | T1: OBS | U1: Data | V1: Lançado12FO | W1: LançadoDrop | X1: NomeEquipe | Y1: ArquivoOrigem
A2: a1 | C2: FLA09 | D2: FORTALEZA | E2: CE | F2: CH04 | G2: PL03 | H2: OLT08 | I2: FLA09-2361 | J2: C1 | K2: Aldeota | L2: R. Barão de Aracati, 747 - Aldeota | M2: -3.7281569 | N2: -38.510175 | O2: a32 | P2: OK | R2: 1564.2 | S2: 60db2b1b | T2: apta | U2: 45820 | X2: ALEF/ CAIKY (85998135803)
A3: a2 | C3: FLA09 | D3: FORTALEZA | E3: CE | F3: CH04 | G3: PL03 | H3: OLT08 | I3: FLA09-2362 | J3: A1 | K3: Aldeota | L3: R. Barão de Aracati, 747 - Aldeota | M3: -3.7281569 | N3: -38.510175 | O3: a32 | P3: OK | R3: 376.2 | S3: 60db2b1b | T3: apta | U3: 45820 | X3: ALEF/ CAIKY (85998135803)
A4: a3 | C4: FLA09 | D4: FORTALEZA | E4: CE | F4: CH04 | G4: PL03 | H4: OLT08 | I4: FLA09-2363 | J4: A1 | K4: Aldeota | L4: R. Barão de Aracati, 747 - Aldeota | M4: -3.7281569 | N4: -38.510175 | O4: a32 | P4: OK | R4: 376.2 | S4: 60db2b1b | T4: apta | U4: 45820 | X4: ALEF/ CAIKY (85998135803)
A5: a4 | C5: FLA09 | D5: FORTALEZA | E5: CE | F5: CH04 | G5: PL03 | H5: OLT08 | I5: FLA09-2364 | J5: A1 | K5: Aldeota | L5: R. Barão de Aracati, 747 - Aldeota | M5: -3.7281569 | N5: -38.510175 | O5: a32 | P5: OK | R5: 376.2 | S5: 60db2b1b | T5: apta | U5: 45820 | X5: ALEF/ CAIKY (85998135803)
A6: a5 | C6: FLA09 | D6: FORTALEZA | E6: CE | F6: CH04 | G6: PL03 | H6: OLT08 | I6: FLA09-2365 | J6: A1 | K6: Aldeota | L6: R. Barão de Aracati, 747 - Aldeota | M6: -3.7281569 | N6: -38.510175 | O6: a32 | P6: OK | R6: 376.2 | S6: 60db2b1b | T6: apta | U6: 45820 | X6: ALEF/ CAIKY (85998135803)
A7: a6 | C7: FLA12 | D7: FORTALEZA | E7: CE | F7: CH02-NOK | G7: PL08 | H7: OLT16 | I7: FLA12-2813 | J7: C1 | K7: Pres. Kennedy | L7: Av. Cearenses, 54 - Pres. Kennedy, Fortaleza - CE | M7: -3.7316557 | N7: -38.566913 | O7: a30 | P7: OK | R7: 1564.2 | S7: 53ef62a7 | T7: apta | U7: 45819 | X7: JOSIMAR/ DANIEL (85992869866)
A8: a7 | C8: FLA12 | D8: FORTALEZA | E8: CE | F8: CH02-NOK | G8: PL08 | H8: OLT16 | I8: FLA12-2814 | J8: A1 | K8: Pres. Kennedy | L8: Av. Cearenses, 54 - Pres. Kennedy, Fortaleza - CE | M8: -3.7316557 | N8: -38.566913 | O8: a30 | P8: OK | R8: 376.2 | S8: 53ef62a7 | T8: apta | U8: 45819 | X8: JOSIMAR/ DANIEL (85992869866)
A9: a8 | C9: FLA12 | D9: FORTALEZA | E9: CE | F9: CH02-NOK | G9: PL08 | H9: OLT16 | I9: FLA12-2815 | J9: A1 | K9: Pres. Kennedy | L9: Av. Cearenses, 54 - Pres. Kennedy, Fortaleza - CE | M9: -3.7316557 | N9: -38.566913 | O9: a30 | P9: OK | R9: 376.2 | S9: 53ef62a7 | T9: apta | U9: 45819 | X9: JOSIMAR/ DANIEL (85992869866)
A10: a9 | C10: FLA12 | D10: FORTALEZA | E10: CE | F10: CH02-NOK | G10: PL08 | H10: OLT16 | I10: FLA12-2816 | J10: A1 | K10: Pres. Kennedy | L10: Av. Cearenses, 54 - Pres. Kennedy, Fortaleza - CE | M10: -3.7316557 | N10: -38.566913 | O10: a30 | P10: OK | R10: 376.2 | S10: 53ef62a7 | T10: apta | U10: 45819 | X10: JOSIMAR/ DANIEL (85992869866)
A11: a10 | C11: FLA12 | D11: FORTALEZA | E11: CE | F11: CH01-NOK | G11: PL08 | H11: OLT03 | I11: FLA12-2849 | J11: A1 | K11: Pres. Kennedy | L11: Av. Cearenses, 54 - Pres. Kennedy, Fortaleza - CE | M11: -3.7316557 | N11: -38.566913 | O11: a30 | P11: OK | R11: 376.2 | S11: 53ef62a7 | T11: apta | U11: 45819 | X11: JOSIMAR/ DANIEL (85992869866)
A12: a11 | C12: FLA12 | D12: FORTALEZA | E12: CE | F12: CH01-NOK | G12: PL08 | H12: OLT03 | I12: FLA12-2850 | J12: A1 | K12: Pres. Kennedy | L12: Av. Cearenses, 54 - Pres. Kennedy, Fortaleza - CE | M12: -3.7316557 | N12: -38.566913 | O12: a30 | P12: OK | R12: 376.2 | S12: 60db2b1b | T12: apta | U12: 45819 | X12: ALEF/ CAIKY (85998135803)
A13: a12 | C13: FLA12 | D13: FORTALEZA | E13: CE | F13: CH01-NOK | G13: PL08 | H13: OLT03 | I13: FLA12-2851 | J13: A1 | K13: Pres. Kennedy | L13: Av. Cearenses, 54 - Pres. Kennedy, Fortaleza - CE | M13: -3.7316557 | N13: -38.566913 | O13: a30 | P13: OK | R13: 376.2 | S13: 60db2b1b | T13: apta | U13: 45819 | X13: ALEF/ CAIKY (85998135803)
... A41: a40 | C41: FLA08 | D41: FORTALEZA | E41: CE | F41: CH01-NOK | G41: PL03 | H41: OLT 07 | I41: FLA08-623 | J41: A1 | K41: Passaré | L41: R. João Granjeiro, 95 - Passaré Fortaleza - CE, 60862-341 | M41: -3.8137417 | N41: -38.531467 | O41: a27 | P41: OK | R41: 376.2 | S41: 53ef62a7 | T41: apta | U41: 45817 | X41: JOSIMAR/ DANIEL (85992869866)
A42: a41 | C42: NTL-17 | D42: NATAL | E42: RN | F42: CH01 | G42: PL08 | H42: OLT 16 | I42: NTL17-1021 | J42: C1 | K42: Lagoa Nova | L42: R. Cel. Auris Coelho, 454-522 - Lagoa Nova, Natal - RN, 59075-050 | M42: -5.825253 | N42: -35.204833 | O42: a2 | P42: OK | Q42: -18.69 | R42: 133.65 | S42: 05dea2e6 | T42: apta | U42: 45827 | X42: PAULO ROBERTO (84996063007)
A43: a42 | C43: NTL17 | D43: NATAL | E43: RN | F43: CH02 | G43: PL01 | H43: OLT 04 | I43: NTL17-1049 | J43: C1 | K43: Lagoa Nova | L43: R. Prof. Antônio Campos, 536-654 - Lagoa Nova, Natal - RN, 59056-090 | M43: -5.8219789 | N43: -35.206354 | O43: a2 | P43: OK | Q43: -19.38 | R43: 133.65 | S43: 05dea2e6 | T43: apta | U43: 45827 | X43: PAULO ROBERTO (84996063007)
A44: a43 | C44: NTL17 | D44: NATAL | E44: RN | F44: CH02 | G44: PL02 | H44: OLT 04 | I44: NTL17-1177 | J44: C1 | K44: Nova Descoberta | L44: R. da Saudade, 1127-1053 - Nova Descoberta, Natal - RN, 59056-400 | M44: -5.8223338 | N44: -35.201845 | O44: a2 | P44: OK | Q44: -18.77 | R44: 133.65 | S44: 05dea2e6 | T44: apta | U44: 45827 | X44: PAULO ROBERTO (84996063007)
A45: a44 | C45: NTL17 | D45: NATAL | E45: RN | F45: CH02 | G45: PL02 | H45: OLT 05 | I45: NTL17-1186 | J45: C1 | K45: Lagoa Nova | L45: Av. Xavier da Silveira - Lagoa Nova, Natal - RN, 59056-530 | M45: -5.8255598 | N45: -35.203485 | O45: a2 | P45: OK | Q45: -18.57 | R45: 133.65 | S45: 5aac2867 | T45: apta | U45: 45825 | X45: EVANILDO/ DELANO (85991198015)
A46: a45 | C46: NTL17 | D46: NATAL | E46: RN | F46: CH02 | G46: PL02 | H46: OLT 09 | I46: NTL17-1218 | J46: C1 | K46: Nova Descoberta | L46: R. Dinarte Mariz Neto, 190 - Nova Descoberta, Natal - RN, 59075-360 | M46: -5.824746 | N46: -35.200292 | O46: a2 | P46: - | Q46: Sem Sinal | R46: 0 | S46: 05dea2e6 | T46: n apta | U46: 45827 | X46: PAULO ROBERTO (84996063007)
A47: a46 | C47: NTL17 | D47: NATAL | E47: RN | F47: CH02 | G47: PL02 | H47: OLT 09 | I47: NTL17-1219 | J47: C1 | K47: Nova Descoberta | L47: R. Dinarte Mariz Neto, 250 - Nova Descoberta, Natal - RN, 59075-360 | M47: -5.8250528 | N47: -35.199769 | O47: a2 | P47: OK | Q47: -18.16 | R47: 133.65 | S47: 05dea2e6 | T47: apta | U47: 45827 | X47: PAULO ROBERTO (84996063007)
A48: a47 | C48: NTL17 | D48: NATAL | E48: RN | F48: CH02 | G48: PL02 | H48: OLT 09 | I48: NTL17-1221 | J48: C1 | K48: Nova Descoberta | L48: R. Dinarte Mariz Neto, 407-341 - Nova Descoberta, Natal - RN, 59075-360 | M48: -5.8254664 | N48: -35.19898 | O48: a2 | P48: OK | Q48: -18.62 | R48: 133.65 | S48: 05dea2e6 | T48: apta | U48: 45827 | X48: PAULO ROBERTO (84996063007)
A49: a48 | C49: NTL17 | D49: NATAL | E49: RN | F49: CH02 | G49: PL02 | H49: OLT 11 | I49: NTL17-1240 | J49: C1 | K49: Lagoa Nova | L49: R. Cel. Auris Coelho, 868 - Lagoa Nova, Natal - RN, 59075-050 | M49: -5.8262669 | N49: -35.201807 | O49: a2 | P49: OK | Q49: -18.17 | R49: 133.65 | S49: 5aac2867 | T49: apta | U49: 45827 | X49: EVANILDO/ DELANO (85991198015)
A50: a49 | C50: NTL17 | D50: NATAL | E50: RN | F50: CH02 | G50: PL02 | H50: OLT 12 | I50: NTL17-1248 | J50: C1 | K50: Nova Descoberta | L50: R. Kerginaldo Cavalcante, 347 - Nova Descoberta, Natal - RN, 59075-240 | M50: -5.8259894 | N50: -35.202977 | O50: a2 | P50: OK | Q50: -18.08 | R50: 133.65 | S50: 5aac2867 | T50: apta | U50: 45825 | X50: EVANILDO/ DELANO (85991198015)
A51: a50 | C51: NTL17 | D51: NATAL | E51: RN | F51: CH02 | G51: PL02 | H51: OLT 14 | I51: NTL17-1258 | J51: C1 | K51: Lagoa Nova | L51: R. Kerginaldo Cavalcante, 462 - Nova Descoberta, Natal - RN, 59075-240 | M51: -5.8268753 | N51: -35.203333 | O51: a2 | P51: OK | Q51: -18.79 | R51: 133.65 | S51: 5aac2867 | T51: apta | U51: 45827 | X51: EVANILDO/ DELANO (85991198015)
A52: a51 | C52: NTL17 | D52: NATAL | E52: RN | F52: CH02 | G52: PL02 | H52: OLT 15 | I52: NTL17-1267 | J52: C1 | K52: Lagoa Nova | L52: R. Cel. Auris Coelho, 900-986 - Lagoa Nova, Natal - RN, 59075-050 | M52: -5.8265258 | N52: -35.201048 | O52: a2 | P52: OK | Q52: -18.37 | R52: 133.65 | S52: 5aac2867 | T52: apta | U52: 45827 | X52: EVANILDO/ DELANO (85991198015)
A53: a52 | C53: NTL17 | D53: NATAL | E53: RN | F53: CH02 | G53: PL02 | H53: OLT 15 | I53: NTL17-1268 | J53: C1 | K53: Lagoa Nova | L53: R. Cel. Auris Coelho, 900-986 - Lagoa Nova, Natal - RN, 59075-050 | M53: -5.8264351 | N53: -35.201306 | O53: a2 | P53: OK | Q53: -17.89 | R53: 133.65 | S53: 5aac2867 | T53: apta | U53: 45827 | X53: EVANILDO/ DELANO (85991198015)
A54: a53 | C54: NTL17 | D54: NATAL | E54: RN | F54: CH02 | G54: PL02 | H54: OLT 15 | I54: NTL17-1270 | J54: C1 | K54: Lagoa Nova | L54: R. Cel. Norton Chaves, 51-57 - Lagoa Nova, Natal - RN, 59075-200 | M54: -5.8284243 | N54: -35.203193 | O54: a2 | P54: OK | Q54: -17.78 | R54: 133.65 | S54: 5aac2867 | T54: apta | U54: 45825 | X54: EVANILDO/ DELANO (85991198015)
A55: a54 | C55: NTL17 | D55: NATAL | E55: RN | F55: CH02 | G55: PL02 | H55: OLT 16 | I55: NTL17-1276 | J55: C1 | K55: Lagoa Nova | L55: R. Dinarte Mariz Neto - Nova Descoberta, Natal - RN, 59075-360 Nova Descoberta | M55: -5.824802 | N55: -35.200005 | O55: a2 | P55: OK | Q55: -18.36 | R55: 133.65 | S55: 05dea2e6 | T55: apta | U55: 45827 | X55: PAULO ROBERTO (84996063007)
A56: a55 | C56: NTL17 | D56: NATAL | E56: RN | F56: CH02 | G56: PL03 | H56: OLT 01 | I56: NTL17-1287 | J56: C1 | K56: Lagoa Nova | L56: R. Cel. Auris Coelho, 1031-963 - Lagoa Nova, Natal - RN, 59075-050 | M56: -5.8267312 | N56: -35.20041 | O56: a2 | P56: OK | Q56: -17.44 | R56: 133.65 | S56: 5aac2867 | T56: apta | U56: 45827 | X56: EVANILDO/ DELANO (85991198015)
A57: a56 | C57: NTL17 | D57: NATAL | E57: RN | F57: CH02 | G57: PL03 | H57: OLT 02 | I57: NTL17-1295 | J57: C1 | L57: R. Laércio Fernandes, 277-197 - Nova Descoberta, Natal - RN, 59075-230 | M57: -5.8257333 | N57: -35.201697 | O57: a2 | P57: OK | Q57: -18.28 | R57: 133.65 | S57: 5aac2867 | T57: apta | U57: 45827 | X57: EVANILDO/ DELANO (85991198015)
A58: a57 | C58: NTL17 | D58: NATAL | E58: RN | F58: CH02 | G58: PL03 | H58: OLT 04 | I58: NTL17-1305 | J58: C1 | L58: R. Padre Raimundo Brasil, 644-856 - Nova Descoberta, Natal - RN, 59075-100 | M58: -5.8257626 | N58: -35.199691 | O58: a2 | P58: OK | Q58: -18.39 | R58: 133.65 | S58: 5aac2867 | T58: apta | U58: 45827 | X58: EVANILDO/ DELANO (85991198015)
A59: a58 | C59: NTL17 | D59: NATAL | E59: RN | F59: CH02 | G59: PL03 | H59: OLT 04 | I59: NTL17-1310 | J59: C1 | K59: Nova Descoberta | L59: R. Padre Raimundo Brasil, 724 - Nova Descoberta, Natal - RN, 59075-100 | M59: -5.825325 | N59: -35.200549 | O59: a2 | P59: OK | Q59: -18.27 | R59: 133.65 | S59: 5aac2867 | T59: apta | U59: 45827 | X59: EVANILDO/ DELANO (85991198015)
A60: a59 | C60: NTL17 | D60: NATAL | E60: RN | F60: CH02 | G60: PL03 | H60: OLT 05 | I60: NTL17-1316 | J60: C1 | L60: R. Padre Raimundo Brasil, 435 - Nova Descoberta, Natal - RN, 59075-100 | M60: -5.8244338 | N60: -35.20211 | O60: a2 | P60: OK | Q60: -19.77 | R60: 133.65 | S60: 21 | T60: apta | U60: 45827 | X60: LEONARDO FERREIRA / PCF4G19 - (85985946718)
A61: a60 | C61: NTL17 | D61: NATAL | E61: RN | F61: CH02 | G61: PL03 | H61: OLT 11 | I61: NTL17-1367 | J61: C1 | L61: R. Padre Raimundo Brasil, 911 - Nova Descoberta, Natal - RN, 59075-100 | M61: -5.8266565 | N61: -35.19806 | O61: a2 | P61: OK | Q61: -18.22 | R61: 133.65 | S61: 21 | T61: apta | U61: 45827 | X61: LEONARDO FERREIRA / PCF4G19 - (85985946718)
A62: a61 | C62: NTL17 | D62: NATAL | E62: RN | F62: CH02 | G62: PL03 | H62: OLT 13 | I62: NTL17-1377 | J62: C1 | K62: Nova Descoberta | L62: Av. Amintas Barros, 512-558 - Nova Descoberta, Natal - RN, 59075-420 | M62: -5.8263924 | N62: -35.194616 | O62: a2 | P62: OK | Q62: -19.16 | R62: 133.65 | S62: 21 | T62: apta | U62: 45827 | X62: LEONARDO FERREIRA / PCF4G19 - (85985946718)
A63: a62 | C63: NTL17 | D63: NATAL | E63: RN | F63: CH02 | G63: PL03 | H63: OLT 13 | I63: NTL17-1378 | J63: C1 | K63: Nova Descoberta Nova Descoberta Nova Descoberta Nova Descoberta Nova Descoberta | L63: R. Themístocles Duarte, 513 - Nova Descoberta, Natal - RN, 59075-420 | M63: -5.8258987 | N63: -35.194914 | O63: a2 | P63: OK | Q63: -18.62 | R63: 133.65 | S63: 21 | T63: apta | U63: 45827 | X63: LEONARDO FERREIRA / PCF4G19 - (85985946718)
A64: a63 | C64: NTL17 | D64: NATAL | E64: RN | F64: CH02 | G64: PL03 | H64: OLT 14 | I64: NTL17-1382 | J64: C1 | K64: Lagoa Nova | L64: Av. Amintas Barros, 4998 - Lagoa Nova, Natal - RN, 59075-250 | M64: -5.8246926 | N64: -35.198063 | O64: a2 | P64: OK | Q64: -20.55 | R64: 133.65 | S64: 21 | T64: apta | U64: 45827 | X64: LEONARDO FERREIRA / PCF4G19 - (85985946718)
A65: a64 | C65: NTL17 | D65: NATAL | E65: RN | F65: CH02 | G65: PL03 | H65: OLT 14 | I65: NTL17-1383 | J65: C1 | K65: Nova Descoberta | L65: R. Nelson Matos, 1868-1886 - Nova Descoberta, Natal - RN, 59075-380 | M65: -5.8242844 | N65: -35.198229 | O65: a2 | P65: OK | Q65: -19.52 | R65: 133.65 | S65: 21 | T65: apta | U65: 45827 | X65: LEONARDO FERREIRA / PCF4G19 - (85985946718)
A66: a65 | C66: NTL17 | D66: NATAL | E66: RN | F66: CH02 | G66: PL04 | H66: OLT 02 | I66: NTL17-1424 | J66: C1 | K66: Lagoa Nova | L66: Av. Sen. Salgado Filho - Lagoa Nova, Natal - RN, 59064-741 | M66: -5.8270408 | N66: -35.209985 | O66: a2 | P66: OK | Q66: -20.72 | R66: 133.65 | S66: 21 | T66: apta | U66: 45825 | X66: LEONARDO FERREIRA / PCF4G19 - (85985946718)
A67: a66 | C67: NTL17 | D67: NATAL | E67: RN | F67: CH02 | G67: PL04 | H67: OLT 04 | I67: NTL17-1439 | J67: C1 | K67: Lagoa Nova | L67: R. do Xisto, 2-106 - Lagoa Nova, Natal - RN, 59076-110 | M67: -5.8292555 | N67: -35.208443 | O67: a2 | P67: OK | Q67: -18.63 | R67: 133.65 | S67: 21 | T67: apta | U67: 45825 | X67: LEONARDO FERREIRA / PCF4G19 - (85985946718)
...

Sheet ImportaCaixa
A1: IdImporta | B1: Data | C1: Arquivo | D1: NomeArquivo
A2: fd09a874 | B2: 45836.976 | C2: ImportaCaixa_Files_/fd09a874.Arquivo.022603.xlsx | D2: Import_280625

Sheet LancaAlares
A1: IdLancamento | B1: Os | C1: De | D1: Para | E1: Previsao | F1: Cenario | G1: Valor | H1: Cabo | I1: Status | J1: Lancado | K1: CenarioReal | L1: ValorReal | M1: DifLanc | N1: OrcadoAtual | O1: Data | P1: Obs | Q1: Equipe | R1: ArquivoOrigem
A2: a1 | B2: a23 | C2: CEOSP2- 04 PA71 | D2: CEOSP4-22-PA71 | E2: 199 | F2: C4 | G2: 900.9 | H2: 12FO | I2: OK | J2: 231 | K2: C4 | L2: 900.9 | M2: 32 | N2: 900.9 | O2: 45835 | Q2: 21
A3: a2 | B3: a23 | C3: NTL01-303/NTL01-932 | D3: NTL01-933 | E3: 89 | F3: C3 | G3: 514.8 | H3: 12FO | I3: OK | J3: 127 | K3: C4 | L3: 900.9 | M3: 38 | N3: 900.9 | O3: 45835 | Q3: 21
A4: a3 | B4: a23 | C4: NTL01-933 | D4: NTL01-934 | E4: 168 | F4: C4 | G4: 900.9 | H4: 12FO | I4: OK | J4: 188 | K4: C4 | L4: 900.9 | M4: 20 | N4: 900.9 | O4: 45835 | Q4: 21
A5: a4 | B5: a23 | C5: CEOSP4-15-PA71 | D5: NTL01-1017 | E5: 127 | F5: C4 | G5: 900.9 | H5: 12FO | I5: OK | J5: 156 | K5: C4 | L5: 900.9 | M5: 29 | N5: 900.9 | O5: 45835 | Q5: 21
A6: a5 | B6: a23 | C6: NTL01-1017 | D6: NTL01-1018 | E6: 188 | F6: C4 | G6: 900.9 | H6: 12FO | I6: OK | J6: 206 | K6: C4 | L6: 900.9 | M6: 18 | N6: 900.9 | O6: 45835 | Q6: 21
A7: a6 | B7: a23 | C7: CEOSP4-14-PA71 | D7: NTL01-1021 | E7: 102 | F7: C4 | G7: 900.9 | H7: 12FO | I7: OK | J7: 139 | K7: C4 | L7: 900.9 | M7: 37 | N7: 900.9 | O7: 45835 | Q7: 21
A8: a7 | B8: a23 | C8: NTL01-1021 | D8: NTL01-1022 | E8: 129 | F8: C4 | G8: 900.9 | H8: 12FO | I8: OK | J8: 164 | K8: C4 | L8: 900.9 | M8: 35 | N8: 900.9 | O8: 45835 | Q8: 21
A9: a8 | B9: a23 | C9: NTL01-1022 | D9: NTL01-1023 | E9: 69 | F9: C3 | G9: 514.8 | H9: 12FO | I9: OK | J9: 89 | K9: C3 | L9: 514.8 | M9: 20 | N9: 514.8 | O9: 45835 | Q9: 21
A10: a9 | B10: a14 | C10: CEOSP-11(MAFG05) | D10: MCW02-2328 | E10: 1200 | F10: LPU | G10: 3972 | H10: 12FO | I10: OK | J10: 1011 | K10: LPU | L10: 3346.41 | M10: 189 | N10: 3346.41 | O10: 45826 | Q10: 6
A11: a10 | B11: a15 | C11: CEODEV-TRONCO-F-29 | D11: CTO-GALPAO-NOVO | E11: 1700 | F11: LPU | G11: 5627 | H11: 12FO | I11: OK | J11: 1691 | K11: LPU | L11: 5597.21 | M11: 9 | N11: 5597.21 | O11: 45831 | Q11: 6
A12: a11 | B12: a43 | C12: POPGIGA+PENTECOSTE | D12: CTOAT-2-PENTECOSTE | E12: 3750 | F12: LPU | G12: 12412.5 | H12: 12FO | I12: OK | J12: 4708 | K12: LPU | L12: 15583.48 | M12: -958 | N12: 15583.48 | O12: 45824 | Q12: 6
A16: ab74c7c8 | B16: 90f54e20 | C16: GOH01-0542/GOH01-0543 | D16: GOH01-0990 | E16: 115 | F16: C4 | G16: 900.9 | H16: 12FO | I16: OK | J16: 115 | K16: C4 | L16: 900.9 | M16: 0 | N16: 900.9 | O16: 45853 | Q16: 0611f994 | R16: LancGOH01-05.07
A17: 5cda6f28 | B17: 90f54e20 | C17: GOH01-0990 | D17: GOH01-0991 | E17: 257 | F17: C4 | G17: 900.9 | H17: 12FO | I17: OK | J17: 252 | K17: C4 | L17: 900.9 | M17: -5 | N17: 900.9 | O17: 45853 | Q17: 0611f994 | R17: LancGOH01-05.07
A18: 17f74e62 | B18: 90f54e20 | C18: GOH01-0991 | D18: GOH01-0992 | E18: 268 | F18: C4 | G18: 900.9 | H18: 12FO | I18: OK | J18: 263 | K18: C4 | L18: 900.9 | M18: -5 | N18: 900.9 | O18: 45853 | Q18: 0611f994 | R18: LancGOH01-05.07
A19: 4b42a7c2 | B19: 90f54e20 | C19: GOH01-0548/GOH01-0986 | D19: GOH01-0989 | E19: 105 | F19: C4 | G19: 900.9 | H19: 12FO | I19: OK | J19: 143 | K19: C4 | L19: 900.9 | M19: 38 | N19: 900.9 | O19: 45853 | Q19: 0611f994 | R19: LancGOH01-05.07
A20: 15b3d85b | B20: 90f54e20 | C20: GOH01-0595 | D20: GOH01-1011 | E20: 183 | F20: C4 | G20: 900.9 | H20: 12FO | I20: OK | J20: 185 | K20: C4 | L20: 900.9 | M20: 2 | N20: 900.9 | O20: 45853 | Q20: 0611f994 | R20: LancGOH01-05.07
A21: 7af20421 | B21: 90f54e20 | C21: GOH01-1011 | D21: GOH01-1012 | E21: 293 | F21: C4 | G21: 900.9 | H21: 12FO | I21: OK | J21: 303 | K21: C5 | L21: 1386 | M21: 10 | N21: 1386 | O21: 45853 | Q21: 0611f994 | R21: LancGOH01-05.07
A22: 10cb0941 | B22: 90f54e20 | C22: GOH01-0590 | D22: GOH01-1009 | E22: 162 | F22: C4 | G22: 900.9 | H22: 12FO | I22: OK | J22: 161 | K22: C4 | L22: 900.9 | M22: -1 | N22: 900.9 | O22: 45853 | Q22: 0611f994 | R22: LancGOH01-05.07
A23: 54e3c6ba | B23: 90f54e20 | C23: GOH01-1009 | D23: GOH01-1010 | E23: 106 | F23: C4 | G23: 900.9 | H23: 12FO | I23: OK | J23: 104 | K23: C4 | L23: 900.9 | M23: -2 | N23: 900.9 | O23: 45853 | Q23: 0611f994 | R23: LancGOH01-05.07
A24: 267043c9 | B24: 90f54e20 | C24: CAIXA-GO-03 - 1/4 | D24: GOH01-0941 | E24: 244 | F24: C4 | G24: 900.9 | H24: 12FO | I24: OK | J24: 329 | K24: C5 | L24: 1386 | M24: 85 | N24: 1386 | O24: 45853 | Q24: 0611f994 | R24: LancGOH01-05.07
A25: a339481e | B25: 90f54e20 | C25: GOH01-0941 | D25: GOH01-0942 | E25: 183 | F25: C4 | G25: 900.9 | H25: 12FO | I25: OK | J25: 447 | K25: C5 | L25: 1386 | M25: 264 | N25: 1386 | O25: 45853 | Q25: 0611f994 | R25: LancGOH01-05.07
A26: b3a9cfbf | B26: 90f54e20 | C26: CAIXA-GO-19 - 1/4 | D26: GOH01-1018 | E26: 374 | F26: C5 | G26: 1386 | H26: 12FO | I26: OK | J26: 385 | K26: C5 | L26: 1386 | M26: 11 | N26: 1386 | O26: 45853 | Q26: 0611f994 | R26: LancGOH01-05.07
A27: be68223f | B27: 90f54e20 | C27: GOH01-1018 | D27: GOH01-1019 | E27: 216 | F27: C4 | G27: 900.9 | H27: 12FO | I27: OK | J27: 254 | K27: C4 | L27: 900.9 | M27: 38 | N27: 900.9 | O27: 45853 | Q27: 0611f994 | R27: LancGOH01-05.07
... A33: e1b8a41a | B33: 90f54e20 | C33: GOH01-0895 | D33: GOH01-0896 | E33: 248 | F33: C4 | G33: 900.9 | H33: 12FO | I33: OK | J33: 245 | K33: C4 | L33: 900.9 | M33: -3 | N33: 900.9 | O33: 45853 | Q33: 0611f994 | R33: LancGOH01-05.07
A34: 18e8a46f | B34: a47 | C34: 332-4 | D34: FLA28-0121 | E34: 185 | F34: C4 | G34: 9009 | H34: 12FO | R34: import_35422645
A35: 9a1c8d70 | B35: a47 | C35: FLA28-0121 | D35: FLA28-0122 | E35: 366 | F35: C5 | G35: 1386 | H35: 12FO | R35: import_35422645
A36: bd077e9c | B36: a47 | C36: FLA28-0122 | D36: FLA28-0123 | E36: 219 | F36: C4 | G36: 9009 | H36: 12FO | R36: import_35422645
A37: 92cd9c5a | B37: a47 | C37: FLA28-0123 | D37: FLA28-0124 | E37: 295 | F37: C4 | G37: 9009 | H37: 12FO | R37: import_35422645
A38: 7cb05231 | B38: a47 | C38: FLA28-0124 | D38: FLA28-0125 | E38: 268 | F38: C4 | G38: 9009 | H38: 12FO | R38: import_35422645
A39: 1b61e6c1 | B39: a47 | C39: FLA28-0125 | D39: FLA28-0126 | E39: 305 | F39: C5 | G39: 1386 | H39: 12FO | R39: import_35422645
A40: 70efb7b5 | B40: a47 | C40: FLA28-0126 | D40: FLA28-0127 | E40: 262 | F40: C4 | G40: 9009 | H40: 12FO | R40: import_35422645
A41: f9626d7a | B41: a47 | C41: FLA28-0127 | D41: FLA28-0128 | E41: 235 | F41: C4 | G41: 9009 | H41: 12FO | R41: import_35422645
A42: 13b0a5ad | B42: a46 | C42: 332-1 - (CE33166) | D42: FLA28-0107 | E42: 147 | F42: C4 | G42: 9009 | H42: 12FO | I42: OK | J42: 152 | K42: C4 | L42: 900.9 | M42: 5 | N42: 900.9 | O42: 45866 | Q42: 6 | R42: import_35332151
A43: d6261b81 | B43: a46 | C43: FLA28-0107 | D43: FLA28-0108 | E43: 152 | F43: C4 | G43: 9009 | H43: 12FO | I43: OK | J43: 158 | K43: C4 | L43: 900.9 | M43: 6 | N43: 900.9 | O43: 45866 | Q43: 6 | R43: import_35332151
A44: 9ac8b3b1 | B44: a46 | C44: FLA28-0108 | D44: FLA28-0109 | E44: 165 | F44: C4 | G44: 9009 | H44: 12FO | I44: OK | J44: 172 | K44: C4 | L44: 900.9 | M44: 7 | N44: 900.9 | O44: 45866 | Q44: 6 | R44: import_35332151
A45: 712cb12e | B45: a46 | C45: FLA28-0109 | D45: FLA28-0110 | E45: 167 | F45: C4 | G45: 9009 | H45: 12FO | I45: OK | J45: 170 | K45: C4 | L45: 900.9 | M45: 3 | N45: 900.9 | O45: 45866 | Q45: 6 | R45: import_35332151
A46: f4945ec9 | B46: a46 | C46: FLA28-0110 | D46: FLA28-0111 | E46: 153 | F46: C4 | G46: 9009 | H46: 12FO | I46: OK | J46: 160 | K46: C4 | L46: 900.9 | M46: 7 | N46: 900.9 | O46: 45866 | Q46: 6 | R46: import_35332151
A47: a8785fa8 | B47: a46 | C47: FLA28-0111 | D47: FLA28-0112 | E47: 235 | F47: C4 | G47: 9009 | H47: 12FO | I47: OK | J47: 236 | K47: C4 | L47: 900.9 | M47: 1 | N47: 900.9 | O47: 45866 | Q47: 6 | R47: import_35332151
A48: 1e9373b0 | B48: a46 | C48: FLA28-0113 | D48: FLA28-0115 | E48: 265 | F48: C4 | G48: 9009 | H48: 12FO | I48: OK | J48: 260 | K48: C4 | L48: 900.9 | M48: -5 | N48: 900.9 | O48: 45866 | Q48: 6 | R48: import_35332151
...

Sheet Din_OS

Sheet Tabela
A1: DT Padrão | B1: Data | C1: Dia da Semana | D1: Entrante | E1: No Prazo | F1: Fora do Prazo | G1: % Prazo | H1: Cabo aplicado | J1: Acumulado | M1: Simulador | N1: Em aberto
A2: =C2 -> 45658 | B2: =IF(C2="","",(TEXT(C2,"DD")&"/"&TEXT(C2,"MM")&"/"&TEXT(C2,"yy"))) -> 01/01/yy | C2: 45658 | D2: =COUNTIF(Os!$AI:$AI,$B2)+3 -> 3 | E2: =COUNTIFS(Os!$AJ:$AJ,$B2,Os!$AK:$AK,"No Prazo",Os!$M:$M,"Concluído") -> 0 | F2: =COUNTIFS(Os!$AJ:$AJ,$B2,Os!$AK:$AK,"Fora do Prazo") -> 0 | G2: =IFERROR(E2/SUM(E2:F2),"-") -> - | J2: Entrante | K2: =SUM(D2:D32) -> 3 | M2: =R13/4 -> 0 | N2: =K2-SUM(K3:K4) -> 3
A3: =A2+1 -> 45659 | B3: =IF(C3="","",(TEXT(C3,"DD")&"/"&TEXT(C3,"MM")&"/"&TEXT(C3,"yy"))) -> 02/01/yy | C3: =C2+1 -> 45659 | D3: =COUNTIF(Os!$AI:$AI,$B3) -> 0 | E3: =COUNTIFS(Os!$AJ:$AJ,$B3,Os!$AK:$AK,"No Prazo",Os!$M:$M,"Concluído") -> 0 | F3: =COUNTIFS(Os!$AJ:$AJ,$B3,Os!$AK:$AK,"Fora do Prazo") -> 0 | G3: =IFERROR(E3/SUM(E3:F3),"-") -> - | J3: No Prazo | K3: =SUM(E2:E32) -> 0
A4: =A3+1 -> 45660 | B4: =IF(C4="","",(TEXT(C4,"DD")&"/"&TEXT(C4,"MM")&"/"&TEXT(C4,"yy"))) -> 03/01/yy | C4: =C3+1 -> 45660 | D4: =COUNTIF(Os!$AI:$AI,$B4) -> 0 | E4: =COUNTIFS(Os!$AJ:$AJ,$B4,Os!$AK:$AK,"No Prazo",Os!$M:$M,"Concluído") -> 0 | F4: =COUNTIFS(Os!$AJ:$AJ,$B4,Os!$AK:$AK,"Fora do Prazo") -> 0 | G4: =IFERROR(E4/SUM(E4:F4),"-") -> - | J4: Fora do Prazo | K4: =SUM(F2:F32) -> 0
A5: =A4+1 -> 45661 | B5: =IF(C5="","",(TEXT(C5,"DD")&"/"&TEXT(C5,"MM")&"/"&TEXT(C5,"yy"))) -> 04/01/yy | C5: =C4+1 -> 45661 | D5: =COUNTIF(Os!$AI:$AI,$B5) -> 0 | E5: =COUNTIFS(Os!$AJ:$AJ,$B5,Os!$AK:$AK,"No Prazo",Os!$M:$M,"Concluído") -> 0 | F5: =COUNTIFS(Os!$AJ:$AJ,$B5,Os!$AK:$AK,"Fora do Prazo") -> 0 | G5: =IFERROR(E5/SUM(E5:F5),"-") -> - | J5: % Prazo | K5: =K3/SUM(K3:K4) -> #DIV/0!
A6: =A5+1 -> 45662 | B6: =IF(C6="","",(TEXT(C6,"DD")&"/"&TEXT(C6,"MM")&"/"&TEXT(C6,"yy"))) -> 05/01/yy | C6: =C5+1 -> 45662 | D6: =COUNTIF(Os!$AI:$AI,$B6) -> 0 | E6: =COUNTIFS(Os!$AJ:$AJ,$B6,Os!$AK:$AK,"No Prazo",Os!$M:$M,"Concluído") -> 0 | F6: =COUNTIFS(Os!$AJ:$AJ,$B6,Os!$AK:$AK,"Fora do Prazo") -> 0 | G6: =IFERROR(E6/SUM(E6:F6),"-") -> -
A7: =A6+1 -> 45663 | B7: =IF(C7="","",(TEXT(C7,"DD")&"/"&TEXT(C7,"MM")&"/"&TEXT(C7,"yy"))) -> 06/01/yy | C7: =C6+1 -> 45663 | D7: =COUNTIF(Os!$AI:$AI,$B7) -> 0 | E7: =COUNTIFS(Os!$AJ:$AJ,$B7,Os!$AK:$AK,"No Prazo",Os!$M:$M,"Concluído") -> 0 | F7: =COUNTIFS(Os!$AJ:$AJ,$B7,Os!$AK:$AK,"Fora do Prazo") -> 0 | G7: =IFERROR(E7/SUM(E7:F7),"-") -> - | Q7: Entrante
A8: =A7+1 -> 45664 | B8: =IF(C8="","",(TEXT(C8,"DD")&"/"&TEXT(C8,"MM")&"/"&TEXT(C8,"yy"))) -> 07/01/yy | C8: =C7+1 -> 45664 | D8: =COUNTIF(Os!$AI:$AI,$B8) -> 0 | E8: =COUNTIFS(Os!$AJ:$AJ,$B8,Os!$AK:$AK,"No Prazo",Os!$M:$M,"Concluído") -> 0 | F8: =COUNTIFS(Os!$AJ:$AJ,$B8,Os!$AK:$AK,"Fora do Prazo") -> 0 | G8: =IFERROR(E8/SUM(E8:F8),"-") -> - | Q8: No Prazo | R8: =4*R9 -> 0
A9: =A8+1 -> 45665 | B9: =IF(C9="","",(TEXT(C9,"DD")&"/"&TEXT(C9,"MM")&"/"&TEXT(C9,"yy"))) -> 08/01/yy | C9: =C8+1 -> 45665 | D9: =COUNTIF(Os!$AI:$AI,$B9) -> 0 | E9: =COUNTIFS(Os!$AJ:$AJ,$B9,Os!$AK:$AK,"No Prazo",Os!$M:$M,"Concluído") -> 0 | F9: =COUNTIFS(Os!$AJ:$AJ,$B9,Os!$AK:$AK,"Fora do Prazo") -> 0 | G9: =IFERROR(E9/SUM(E9:F9),"-") -> - | Q9: Fora do Prazo | R9: =K4 -> 0
A10: =A9+1 -> 45666 | B10: =IF(C10="","",(TEXT(C10,"DD")&"/"&TEXT(C10,"MM")&"/"&TEXT(C10,"yy"))) -> 09/01/yy | C10: =C9+1 -> 45666 | D10: =COUNTIF(Os!$AI:$AI,$B10) -> 0 | E10: =COUNTIFS(Os!$AJ:$AJ,$B10,Os!$AK:$AK,"No Prazo",Os!$M:$M,"Concluído") -> 0 | F10: =COUNTIFS(Os!$AJ:$AJ,$B10,Os!$AK:$AK,"Fora do Prazo") -> 0 | G10: =IFERROR(E10/SUM(E10:F10),"-") -> - | Q10: % Prazo | R10: =R8/SUM(R8:R9) -> #DIV/0!
A11: =A10+1 -> 45667 | B11: =IF(C11="","",(TEXT(C11,"DD")&"/"&TEXT(C11,"MM")&"/"&TEXT(C11,"yy"))) -> 10/01/yy | C11: =C10+1 -> 45667 | D11: =COUNTIF(Os!$AI:$AI,$B11) -> 0 | E11: =COUNTIFS(Os!$AJ:$AJ,$B11,Os!$AK:$AK,"No Prazo",Os!$M:$M,"Concluído") -> 0 | F11: =COUNTIFS(Os!$AJ:$AJ,$B11,Os!$AK:$AK,"Fora do Prazo") -> 0 | G11: =IFERROR(E11/SUM(E11:F11),"-") -> -
A12: =A11+1 -> 45668 | B12: =IF(C12="","",(TEXT(C12,"DD")&"/"&TEXT(C12,"MM")&"/"&TEXT(C12,"yy"))) -> 11/01/yy | C12: =C11+1 -> 45668 | D12: =COUNTIF(Os!$AI:$AI,$B12) -> 0 | E12: =COUNTIFS(Os!$AJ:$AJ,$B12,Os!$AK:$AK,"No Prazo",Os!$M:$M,"Concluído") -> 0 | F12: =COUNTIFS(Os!$AJ:$AJ,$B12,Os!$AK:$AK,"Fora do Prazo") -> 0 | G12: =IFERROR(E12/SUM(E12:F12),"-") -> - | Q12: Reparos que preciso fazer para está NO PRAZO
A13: =A12+1 -> 45669 | B13: =IF(C13="","",(TEXT(C13,"DD")&"/"&TEXT(C13,"MM")&"/"&TEXT(C13,"yy"))) -> 12/01/yy | C13: =C12+1 -> 45669 | D13: =COUNTIF(Os!$AI:$AI,$B13) -> 0 | E13: =COUNTIFS(Os!$AJ:$AJ,$B13,Os!$AK:$AK,"No Prazo",Os!$M:$M,"Concluído") -> 0 | F13: =COUNTIFS(Os!$AJ:$AJ,$B13,Os!$AK:$AK,"Fora do Prazo") -> 0 | G13: =IFERROR(E13/SUM(E13:F13),"-") -> - | R13: =R8-K3 -> 0
A14: =A13+1 -> 45670 | B14: =IF(C14="","",(TEXT(C14,"DD")&"/"&TEXT(C14,"MM")&"/"&TEXT(C14,"yy"))) -> 13/01/yy | C14: =C13+1 -> 45670 | D14: =COUNTIF(Os!$AI:$AI,$B14) -> 0 | E14: =COUNTIFS(Os!$AJ:$AJ,$B14,Os!$AK:$AK,"No Prazo",Os!$M:$M,"Concluído") -> 0 | F14: =COUNTIFS(Os!$AJ:$AJ,$B14,Os!$AK:$AK,"Fora do Prazo") -> 0 | G14: =IFERROR(E14/SUM(E14:F14),"-") -> -
A15: =A14+1 -> 45671 | B15: =IF(C15="","",(TEXT(C15,"DD")&"/"&TEXT(C15,"MM")&"/"&TEXT(C15,"yy"))) -> 14/01/yy | C15: =C14+1 -> 45671 | D15: =COUNTIF(Os!$AI:$AI,$B15) -> 0 | E15: =COUNTIFS(Os!$AJ:$AJ,$B15,Os!$AK:$AK,"No Prazo",Os!$M:$M,"Concluído") -> 0 | F15: =COUNTIFS(Os!$AJ:$AJ,$B15,Os!$AK:$AK,"Fora do Prazo") -> 0 | G15: =IFERROR(E15/SUM(E15:F15),"-") -> -
A16: =A15+1 -> 45672 | B16: =IF(C16="","",(TEXT(C16,"DD")&"/"&TEXT(C16,"MM")&"/"&TEXT(C16,"yy"))) -> 15/01/yy | C16: =C15+1 -> 45672 | D16: =COUNTIF(Os!$AI:$AI,$B16) -> 0 | E16: =COUNTIFS(Os!$AJ:$AJ,$B16,Os!$AK:$AK,"No Prazo",Os!$M:$M,"Concluído") -> 0 | F16: =COUNTIFS(Os!$AJ:$AJ,$B16,Os!$AK:$AK,"Fora do Prazo") -> 0 | G16: =IFERROR(E16/SUM(E16:F16),"-") -> - | K16: * Qtde por tecnico
A17: =A16+1 -> 45673 | B17: =IF(C17="","",(TEXT(C17,"DD")&"/"&TEXT(C17,"MM")&"/"&TEXT(C17,"yy"))) -> 16/01/yy | C17: =C16+1 -> 45673 | D17: =COUNTIF(Os!$AI:$AI,$B17) -> 0 | E17: =COUNTIFS(Os!$AJ:$AJ,$B17,Os!$AK:$AK,"No Prazo",Os!$M:$M,"Concluído") -> 0 | F17: =COUNTIFS(Os!$AJ:$AJ,$B17,Os!$AK:$AK,"Fora do Prazo") -> 0 | G17: =IFERROR(E17/SUM(E17:F17),"-") -> - | K17: * Do concluido - qto teve cabo apliacado
A18: =A17+1 -> 45674 | B18: =IF(C18="","",(TEXT(C18,"DD")&"/"&TEXT(C18,"MM")&"/"&TEXT(C18,"yy"))) -> 17/01/yy | C18: =C17+1 -> 45674 | D18: =COUNTIF(Os!$AI:$AI,$B18) -> 0 | E18: =COUNTIFS(Os!$AJ:$AJ,$B18,Os!$AK:$AK,"No Prazo",Os!$M:$M,"Concluído") -> 0 | F18: =COUNTIFS(Os!$AJ:$AJ,$B18,Os!$AK:$AK,"Fora do Prazo") -> 0 | G18: =IFERROR(E18/SUM(E18:F18),"-") -> - | K18: * Qtos reparos pode perder para ainda ficar na meta - com virgula
A19: =A18+1 -> 45675 | B19: =IF(C19="","",(TEXT(C19,"DD")&"/"&TEXT(C19,"MM")&"/"&TEXT(C19,"yy"))) -> 18/01/yy | C19: =C18+1 -> 45675 | D19: =COUNTIF(Os!$AI:$AI,$B19) -> 0 | E19: =COUNTIFS(Os!$AJ:$AJ,$B19,Os!$AK:$AK,"No Prazo",Os!$M:$M,"Concluído") -> 0 | F19: =COUNTIFS(Os!$AJ:$AJ,$B19,Os!$AK:$AK,"Fora do Prazo") -> 0 | G19: =IFERROR(E19/SUM(E19:F19),"-") -> - | K19: * Pareto com os responsaveis pela causa
A20: =A19+1 -> 45676 | B20: =IF(C20="","",(TEXT(C20,"DD")&"/"&TEXT(C20,"MM")&"/"&TEXT(C20,"yy"))) -> 19/01/yy | C20: =C19+1 -> 45676 | D20: =COUNTIF(Os!$AI:$AI,$B20) -> 0 | E20: =COUNTIFS(Os!$AJ:$AJ,$B20,Os!$AK:$AK,"No Prazo",Os!$M:$M,"Concluído") -> 0 | F20: =COUNTIFS(Os!$AJ:$AJ,$B20,Os!$AK:$AK,"Fora do Prazo") -> 0 | G20: =IFERROR(E20/SUM(E20:F20),"-") -> - | K20: * SImular resultado expurgando causas diferentes sem acesso cliente, sem acesso ARd
A21: =A20+1 -> 45677 | B21: =IF(C21="","",(TEXT(C21,"DD")&"/"&TEXT(C21,"MM")&"/"&TEXT(C21,"yy"))) -> 20/01/yy | C21: =C20+1 -> 45677 | D21: =COUNTIF(Os!$AI:$AI,$B21) -> 0 | E21: =COUNTIFS(Os!$AJ:$AJ,$B21,Os!$AK:$AK,"No Prazo",Os!$M:$M,"Concluído") -> 0 | F21: =COUNTIFS(Os!$AJ:$AJ,$B21,Os!$AK:$AK,"Fora do Prazo") -> 0 | G21: =IFERROR(E21/SUM(E21:F21),"-") -> -
A22: =A21+1 -> 45678 | B22: =IF(C22="","",(TEXT(C22,"DD")&"/"&TEXT(C22,"MM")&"/"&TEXT(C22,"yy"))) -> 21/01/yy | C22: =C21+1 -> 45678 | D22: =COUNTIF(Os!$AI:$AI,$B22) -> 0 | E22: =COUNTIFS(Os!$AJ:$AJ,$B22,Os!$AK:$AK,"No Prazo",Os!$M:$M,"Concluído") -> 0 | F22: =COUNTIFS(Os!$AJ:$AJ,$B22,Os!$AK:$AK,"Fora do Prazo") -> 0 | G22: =IFERROR(E22/SUM(E22:F22),"-") -> -
A23: =A22+1 -> 45679 | B23: =IF(C23="","",(TEXT(C23,"DD")&"/"&TEXT(C23,"MM")&"/"&TEXT(C23,"yy"))) -> 22/01/yy | C23: =C22+1 -> 45679 | D23: =COUNTIF(Os!$AI:$AI,$B23) -> 0 | E23: =COUNTIFS(Os!$AJ:$AJ,$B23,Os!$AK:$AK,"No Prazo",Os!$M:$M,"Concluído") -> 0 | F23: =COUNTIFS(Os!$AJ:$AJ,$B23,Os!$AK:$AK,"Fora do Prazo") -> 0 | G23: =IFERROR(E23/SUM(E23:F23),"-") -> -
A24: =A23+1 -> 45680 | B24: =IF(C24="","",(TEXT(C24,"DD")&"/"&TEXT(C24,"MM")&"/"&TEXT(C24,"yy"))) -> 23/01/yy | C24: =C23+1 -> 45680 | D24: =COUNTIF(Os!$AI:$AI,$B24) -> 0 | E24: =COUNTIFS(Os!$AJ:$AJ,$B24,Os!$AK:$AK,"No Prazo",Os!$M:$M,"Concluído") -> 0 | F24: =COUNTIFS(Os!$AJ:$AJ,$B24,Os!$AK:$AK,"Fora do Prazo") -> 0 | G24: =IFERROR(E24/SUM(E24:F24),"-") -> -
A25: =A24+1 -> 45681 | B25: =IF(C25="","",(TEXT(C25,"DD")&"/"&TEXT(C25,"MM")&"/"&TEXT(C25,"yy"))) -> 24/01/yy | C25: =C24+1 -> 45681 | D25: =COUNTIF(Os!$AI:$AI,$B25) -> 0 | E25: =COUNTIFS(Os!$AJ:$AJ,$B25,Os!$AK:$AK,"No Prazo",Os!$M:$M,"Concluído") -> 0 | F25: =COUNTIFS(Os!$AJ:$AJ,$B25,Os!$AK:$AK,"Fora do Prazo") -> 0 | G25: =IFERROR(E25/SUM(E25:F25),"-") -> -
A26: =A25+1 -> 45682 | B26: =IF(C26="","",(TEXT(C26,"DD")&"/"&TEXT(C26,"MM")&"/"&TEXT(C26,"yy"))) -> 25/01/yy | C26: =C25+1 -> 45682 | D26: =COUNTIF(Os!$AI:$AI,$B26) -> 0 | E26: =COUNTIFS(Os!$AJ:$AJ,$B26,Os!$AK:$AK,"No Prazo",Os!$M:$M,"Concluído") -> 0 | F26: =COUNTIFS(Os!$AJ:$AJ,$B26,Os!$AK:$AK,"Fora do Prazo") -> 0 | G26: =IFERROR(E26/SUM(E26:F26),"-") -> -
A27: =A26+1 -> 45683 | B27: =IF(C27="","",(TEXT(C27,"DD")&"/"&TEXT(C27,"MM")&"/"&TEXT(C27,"yy"))) -> 26/01/yy | C27: =C26+1 -> 45683 | D27: =COUNTIF(Os!$AI:$AI,$B27) -> 0 | E27: =COUNTIFS(Os!$AJ:$AJ,$B27,Os!$AK:$AK,"No Prazo",Os!$M:$M,"Concluído") -> 0 | F27: =COUNTIFS(Os!$AJ:$AJ,$B27,Os!$AK:$AK,"Fora do Prazo") -> 0 | G27: =IFERROR(E27/SUM(E27:F27),"-") -> -
A28: =A27+1 -> 45684 | B28: =IF(C28="","",(TEXT(C28,"DD")&"/"&TEXT(C28,"MM")&"/"&TEXT(C28,"yy"))) -> 27/01/yy | C28: =C27+1 -> 45684 | D28: =COUNTIF(Os!$AI:$AI,$B28) -> 0 | E28: =COUNTIFS(Os!$AJ:$AJ,$B28,Os!$AK:$AK,"No Prazo",Os!$M:$M,"Concluído") -> 0 | F28: =COUNTIFS(Os!$AJ:$AJ,$B28,Os!$AK:$AK,"Fora do Prazo") -> 0 | G28: =IFERROR(E28/SUM(E28:F28),"-") -> -
A29: =A28+1 -> 45685 | B29: =IF(C29="","",(TEXT(C29,"DD")&"/"&TEXT(C29,"MM")&"/"&TEXT(C29,"yy"))) -> 28/01/yy | C29: =C28+1 -> 45685 | D29: =COUNTIF(Os!$AI:$AI,$B29) -> 0 | E29: =COUNTIFS(Os!$AJ:$AJ,$B29,Os!$AK:$AK,"No Prazo",Os!$M:$M,"Concluído") -> 0 | F29: =COUNTIFS(Os!$AJ:$AJ,$B29,Os!$AK:$AK,"Fora do Prazo") -> 0 | G29: =IFERROR(E29/SUM(E29:F29),"-") -> -
A30: =A29+1 -> 45686 | B30: =IF(C30="","",(TEXT(C30,"DD")&"/"&TEXT(C30,"MM")&"/"&TEXT(C30,"yy"))) -> 29/01/yy | C30: =C29+1 -> 45686 | D30: =COUNTIF(Os!$AI:$AI,$B30) -> 0 | E30: =COUNTIFS(Os!$AJ:$AJ,$B30,Os!$AK:$AK,"No Prazo",Os!$M:$M,"Concluído") -> 0 | F30: =COUNTIFS(Os!$AJ:$AJ,$B30,Os!$AK:$AK,"Fora do Prazo") -> 0 | G30: =IFERROR(E30/SUM(E30:F30),"-") -> -
A31: =A30+1 -> 45687 | B31: =IF(C31="","",(TEXT(C31,"DD")&"/"&TEXT(C31,"MM")&"/"&TEXT(C31,"yy"))) -> 30/01/yy | C31: =C30+1 -> 45687 | D31: =COUNTIF(Os!$AI:$AI,$B31) -> 0 | E31: =COUNTIFS(Os!$AJ:$AJ,$B31,Os!$AK:$AK,"No Prazo",Os!$M:$M,"Concluído") -> 0 | F31: =COUNTIFS(Os!$AJ:$AJ,$B31,Os!$AK:$AK,"Fora do Prazo") -> 0 | G31: =IFERROR(E31/SUM(E31:F31),"-") -> -
A32: =A31+1 -> 45688 | B32: =IF(C32="","",(TEXT(C32,"DD")&"/"&TEXT(C32,"MM")&"/"&TEXT(C32,"yy"))) -> 31/01/yy | C32: =C31+1 -> 45688 | D32: =COUNTIF(Os!$AI:$AI,$B32) -> 0 | E32: =COUNTIFS(Os!$AJ:$AJ,$B32,Os!$AK:$AK,"No Prazo",Os!$M:$M,"Concluído") -> 0 | F32: =COUNTIFS(Os!$AJ:$AJ,$B32,Os!$AK:$AK,"Fora do Prazo") -> 0 | G32: =IFERROR(E32/SUM(E32:F32),"-") -> -
E33: =IF(F33="","",$E$2)
E34: =IF(F34="","",$E$2)

Sheet Motivo
A1: IdMotivo | B1: CodMotivo | C1: Descricao | D1: Tipo
A2: MOT1 | B2: 0 | C2: INVENTÁRIO | D2: INVENTÁRIO
A3: MOT2 | B3: 10 | C3: ENTRADA DO CLIENTE | D3: ENTRADA
A4: MOT3 | B4: 11 | C4: ENTRADA DE O.S | D4: ENTRADA
A5: MOT4 | B5: 12 | C5: COMPRA DE MATERIAL PRÓPRIO | D5: ENTRADA
A6: MOT5 | B6: 20 | C6: BAIXA DE MATERIAL | D6: SAIDA
A7: MOT6 | B7: 21 | C7: DEVOLUÇÃO PARA CLIENTE | D7: SAIDA
A8: MOT7 | B8: 30 | C8: TRANSFERENCIA ENTRE ALMOXARIFADOS | D8: TRANSFERENCIA

Sheet TpMov
A1: IdTpMov | B1: TpMov | C1: Tipo
A2: ENTRADA | B2: ENTRADA | C2: tec
A3: SAIDA | B3: SAIDA | C3: tec
A4: INVENTÁRIO | B4: INVENTÁRIO
A5: TRANSFERENCIA | B5: TRANSFERENCIA

Sheet Din_Pareto
A1: #REF! | C1: Paret. | D1: cont | E1: cont2 | F1: x | G1: Perda | H1: Contagem | I1: Pareto
C2: =B2/SUM($B$2:$B$29) -> #DIV/0! | D2: 0.01 | E2: =B2+D2 -> 0.01 | G2: {=IF(A2="","Sem dados", INDEX(A:A,MATCH($H2,E:E,0)))} -> Sem dados | H2: =LARGE($E$2:$E$6,1) -> 0.05 | I2: =H2/SUM($H$2:$H$6) -> 0.33333333
C3: =B3/SUM($B$2:$B$29)+C2 -> #DIV/0! | D3: =D2+0.01 -> 0.02 | E3: =B3+D3 -> 0.02 | G3: =INDEX(A:A,MATCH($H3,E:E,0)) -> 0 | H3: =LARGE($E$2:$E$6,2) -> 0.04 | I3: =H3/SUM($H$2:$H$6)+I2 -> 0.6
C4: =B4/SUM($B$2:$B$29)+C3 -> #DIV/0! | D4: =D3+0.01 -> 0.03 | E4: =B4+D4 -> 0.03 | G4: =INDEX(A:A,MATCH($H4,E:E,0)) -> 0 | H4: =LARGE($E$2:$E$6,3) -> 0.03 | I4: =H4/SUM($H$2:$H$6)+I3 -> 0.8
C5: =B5/SUM($B$2:$B$29)+C4 -> #DIV/0! | D5: =D4+0.01 -> 0.04 | E5: =B5+D5 -> 0.04 | G5: =INDEX(A:A,MATCH($H5,E:E,0)) -> 0 | H5: =LARGE($E$2:$E$6,4) -> 0.02 | I5: =H5/SUM($H$2:$H$6)+I4 -> 0.93333333
C6: =B6/SUM($B$2:$B$29)+C5 -> #DIV/0! | D6: =D5+0.01 -> 0.05 | E6: =B6+D6 -> 0.05 | G6: =INDEX(A:A,MATCH($H6,E:E,0)) -> 0 | H6: =LARGE($E$2:$E$6,5) -> 0.01 | I6: =H6/SUM($H$2:$H$6)+I5 -> 1

Sheet Tab_Contrato
A1: Contrato | B1: Cliente
A3: Unifor
A4: MobWIre
A5: Tecnomulti

Sheet Tab_Obras
A1: Obra
A2: Obras Crato
A3: Obras Ceará
A4: Equipes Classe C
A5: Equipes Classe F
A6: Preventivas
A7: LD - PACOTI
A8: Obras Sergipe
A9: Equipes Classe F - (MA)
A10: Cab. Estruturado (Unifor)
A11: Equipes Reparadores
A12: B2B - RN
... A18: Equipes Disposição

Sheet Tab_Responsavel
A1: Responsavel | B1: Cliente
A2: Celso | B2: R2
A3: Marquinho | B3: R2
A4: Rógerio | B4: R2
A5: Clodomar | B5: R2
A6: Djair | B6: R2
A7: Batista | B7: R2
A8: Arlison | B8: R2
A9: Carlos Augusto | B9: R2
A10: Marcelo | B10: R2
A11: Adenilson | B11: UNIFOR
A12: Clebio | B12: R2
... A15: Adriano | B15: R2
A16: Oberdan
A17: Jonas
A18: Frank
A19: ANGELO FABRICIO | B19: R2
A20: Cleiton
A21: MARCILIO

Sheet Tab_Produtos
A1: Produto | B1: Cliente
A2: Cabeamento Estruturado
A3: Wi-Fi
A4: Equipe Disposição
A5: Camera PTZ
A6: Camera Fixa
A7: Adequação Enel
A8: Construção de Rede - LD
A9: Reparo - Classe F
A10: Reparo - Classe C
A11: Link de Dados
A12: Raiser
A13: Obra B2B
... A18: Vistoria de Poste
A19: Reparo - GPON | B19: VIVO
A20: Reparo - BBR | B20: VIVO
A21: Preventiva Postes
A22: Formatação de Sites
A25: Reparo - Disp - VIVO - Classe F | B25: VIVO
A26: Reparo - Disp - VIVO - Classe C | B26: VIVO
A27: Reparo - Disp - V.tal - Classe F | B27: V.tal
A28: Contrato - GPON | B28: R2 - VIVO
A29: Contrato B2B - GPON | B29: R2 - VIVO

Sheet Tab_Cidades
A1: Cidades
A2: Alta Floresta D´oeste - RO
A3: Ariquemes - RO
A4: Cabixi - RO
A5: Cacoal - RO
A6: Cerejeiras - RO
A7: Colorado do Oeste - RO
A8: Corumbiara - RO
A9: Costa Marques - RO
A10: Espigão D´oeste - RO
A11: Guajará-mirim - RO
A12: Jaru - RO
... A5578: b46e1afe

Sheet Tab_StatusOperacao
A1: Status_Operacao
A2: Lib. Execução
A3: Em Execução
A4: Aguard. Liberação
A5: Concluído
A6: Pend. Cliente
A7: Aguard. Material
A8: Cancelado
A9: Pend. Ativação
A10: Iniciar
A11: Declinado sem Acesso

Sheet Tab_StatusMedicao
A1: Status_Medicao
A2: Não Medido
A3: Em Medição
A4: Medição Concluída
A5: Medição Aceita
A6: NF Emitida
A7: Medição Enviada
A8: NF Recebida

Sheet Indicadores
A1: Status de Operação | B1: =COUNTA(Os!B:B)-1 -> 0 | D1: Status de Operação | E1: =SUM(Os!L:L) -> 2130253
A2: Concluído | B2: =COUNTIF(Os!M:M,A2) -> 377 | D2: Em Medição | E2: =SUMIF(Os!Q:Q,D2,Os!L:L) -> 0
A3: Realização Física | B3: =B2/B1 -> #DIV/0! | D3: Não Medido | E3: =SUMIF(Os!Q:Q,D3,Os!L:L) -> 465462.35
D4: (-) Realizado | E4: =E1-SUM(E2:E3) -> 1664790.7
D5: Realização Financeira | E5: =E4/E1 -> 0.78149903

Sheet TAB Indicadores
A1: Total Realizado | B1: Real Opera | C1: R$ em Medição | D1: R$ Não Medido | E1: Valor Serviço 2 | F1: Real Financeiro
A2: =IF(#REF!<>"",1,0) -> #REF! | B2: =IF(#REF!="Concluído",1,"") -> #REF! | C2: =IFERROR(SUMIF(#REF!,"Em Medição",#REF!),"") | D2: =IFERROR(SUMIF(#REF!,"Não Medido",#REF!),"") | E2: =IFERROR(#REF!,"") | F2: =E2-SUM(C2:D2) -> #VALUE!
A3: =IF(#REF!<>"",1,0) -> #REF! | B3: =IF(#REF!="Concluído",1,"") -> #REF! | C3: =IFERROR(SUMIF(#REF!,"Em Medição",#REF!),"") | D3: =IFERROR(SUMIF(#REF!,"Não Medido",#REF!),"") | E3: =IFERROR(#REF!,"") | F3: =E3-SUM(C3:D3) -> #VALUE!
A4: =IF(#REF!<>"",1,0) -> #REF! | B4: =IF(#REF!="Concluído",1,"") -> #REF! | C4: =IFERROR(SUMIF(#REF!,"Em Medição",#REF!),"") | D4: =IFERROR(SUMIF(#REF!,"Não Medido",#REF!),"") | E4: =IFERROR(#REF!,"") | F4: =E4-SUM(C4:D4) -> #VALUE!
A5: =IF(#REF!<>"",1,0) -> #REF! | B5: =IF(#REF!="Concluído",1,"") -> #REF! | C5: =IFERROR(SUMIF(#REF!,"Em Medição",#REF!),"") | D5: =IFERROR(SUMIF(#REF!,"Não Medido",#REF!),"") | E5: =IFERROR(#REF!,"") | F5: =E5-SUM(C5:D5) -> #VALUE!
A6: =IF(#REF!<>"",1,0) -> #REF! | B6: =IF(#REF!="Concluído",1,"") -> #REF! | C6: =IFERROR(SUMIF(#REF!,"Em Medição",#REF!),"") | D6: =IFERROR(SUMIF(#REF!,"Não Medido",#REF!),"") | E6: =IFERROR(#REF!,"") | F6: =E6-SUM(C6:D6) -> #VALUE!
A7: =IF(#REF!<>"",1,0) -> #REF! | B7: =IF(#REF!="Concluído",1,"") -> #REF! | C7: =IFERROR(SUMIF(#REF!,"Em Medição",#REF!),"") | D7: =IFERROR(SUMIF(#REF!,"Não Medido",#REF!),"") | E7: =IFERROR(#REF!,"") | F7: =E7-SUM(C7:D7) -> #VALUE!
A8: =IF(#REF!<>"",1,0) -> #REF! | B8: =IF(#REF!="Concluído",1,"") -> #REF! | C8: =IFERROR(SUMIF(#REF!,"Em Medição",#REF!),"") | D8: =IFERROR(SUMIF(#REF!,"Não Medido",#REF!),"") | E8: =IFERROR(#REF!,"") | F8: =E8-SUM(C8:D8) -> #VALUE!
A9: =IF(#REF!<>"",1,0) -> #REF! | B9: =IF(#REF!="Concluído",1,"") -> #REF! | C9: =IFERROR(SUMIF(#REF!,"Em Medição",#REF!),"") | D9: =IFERROR(SUMIF(#REF!,"Não Medido",#REF!),"") | E9: =IFERROR(#REF!,"") | F9: =E9-SUM(C9:D9) -> #VALUE!
A10: =IF(#REF!<>"",1,0) -> #REF! | B10: =IF(#REF!="Concluído",1,"") -> #REF! | C10: =IFERROR(SUMIF(#REF!,"Em Medição",#REF!),"") | D10: =IFERROR(SUMIF(#REF!,"Não Medido",#REF!),"") | E10: =IFERROR(#REF!,"") | F10: =E10-SUM(C10:D10) -> #VALUE!
A11: =IF(#REF!<>"",1,0) -> #REF! | B11: =IF(#REF!="Concluído",1,"") -> #REF! | C11: =IFERROR(SUMIF(#REF!,"Em Medição",#REF!),"") | D11: =IFERROR(SUMIF(#REF!,"Não Medido",#REF!),"") | E11: =IFERROR(#REF!,"") | F11: =E11-SUM(C11:D11) -> #VALUE!
A12: =IF(#REF!<>"",1,0) -> #REF! | B12: =IF(#REF!="Concluído",1,"") -> #REF! | C12: =IFERROR(SUMIF(#REF!,"Em Medição",#REF!),"") | D12: =IFERROR(SUMIF(#REF!,"Não Medido",#REF!),"") | E12: =IFERROR(#REF!,"") | F12: =E12-SUM(C12:D12) -> #VALUE!
A13: =IF(#REF!<>"",1,0) -> #REF! | B13: =IF(#REF!="Concluído",1,"") -> #REF! | C13: =IFERROR(SUMIF(#REF!,"Em Medição",#REF!),"") | D13: =IFERROR(SUMIF(#REF!,"Não Medido",#REF!),"") | E13: =IFERROR(#REF!,"") | F13: =E13-SUM(C13:D13) -> #VALUE!
... A3982: =IF(#REF!<>"",1,0) -> #REF! | B3982: =IF(#REF!="Concluído",1,"") -> #REF! | C3982: =IFERROR(SUMIF(#REF!,"Em Medição",#REF!),"") | D3982: =IFERROR(SUMIF(#REF!,"Não Medido",#REF!),"") | E3982: =IFERROR(#REF!,"") | F3982: =E3982-SUM(C3982:D3982) -> #VALUE!

Sheet Tabela dinâmica 1

Sheet Equipes
A1: IdEquipe | B1: CodEquipe | C1: NomeEquipe | D1: Prestadora | E1: Classificacao | F1: Unidade | G1: DescEquipe | H1: Centro
A2: 1 | B2: XON-CE | C2: ALMOXARIFADO INTERNO (CEARÁ) | D2: ALARES | E2: ALMOXARIFADO | F2: CE | G2: =CONCATENATE(B2," - ",C2) -> XON-CE - ALMOXARIFADO INTERNO (CEARÁ) | H2: ALMOXARIFADO
A3: 3 | B3: XON-PB | C3: ALMOXARIFADO INTERNO (PARAÍBA) | D3: X-ON | E3: ALMOXARIFADO | F3: PB | G3: =CONCATENATE(B3," - ",C3) -> XON-PB - ALMOXARIFADO INTERNO (PARAÍBA) | H3: ALMOXARIFADO
A4: 4 | B4: XON-RN | C4: ALMOXARIFADO INTERNO (RIO GRANDE DO NORTE) | D4: X-ON | E4: ALMOXARIFADO | F4: RN | G4: =CONCATENATE(B4," - ",C4) -> XON-RN - ALMOXARIFADO INTERNO (RIO GRANDE DO NORTE) | H4: ALMOXARIFADO
A5: 5 | B5: XRN-03 | C5: ELY/ ANDERSON (84986690564) | D5: ALARES | E5: IMPLANTAÇÃO | F5: RN | G5: =CONCATENATE(B5," - ",C5) -> XRN-03 - ELY/ ANDERSON (84986690564) | H5: LANÇAMENTO
A6: 6 | B6: XCE-01 | C6: BATISTA E JAIR / (85991669867) | D6: ALARES | E6: IMPLANTAÇÃO | F6: CE | G6: =CONCATENATE(B6," - ",C6) -> XCE-01 - BATISTA E JAIR / (85991669867) | H6: LANÇAMENTO
A7: 7 | B7: XRN-02 | C7: ALDENIR (85991743369) | D7: ALARES | E7: IMPLANTAÇÃO | F7: RN | G7: =CONCATENATE(B7," - ",C7) -> XRN-02 - ALDENIR (85991743369) | H7: LANÇAMENTO
A8: 11 | B8: XCE-02 | C8: FRANCISCO JOSE/ FERNANDO (85988636495) | D8: ALARES | E8: IMPLANTAÇÃO | F8: CE | G8: =CONCATENATE(B8," - ",C8) -> XCE-02 - FRANCISCO JOSE/ FERNANDO (85988636495) | H8: LANÇAMENTO
A9: 15 | B9: XCE-13 | C9: JEFESSON FREITAS/ ANDERSON (85981351805) | D9: ALARES | E9: IMPLANTAÇÃO | F9: CE | G9: =CONCATENATE(B9," - ",C9) -> XCE-13 - JEFESSON FREITAS/ ANDERSON (85981351805) | H9: FUSÃO
A10: 17 | B10: XCE-04 | C10: JOAO VICTOR | D10: ALARES | E10: IMPLANTAÇÃO | F10: CE | G10: =CONCATENATE(B10," - ",C10) -> XCE-04 - JOAO VICTOR | H10: FUSÃO
A11: 21 | B11: XCE-05 | C11: LEONARDO FERREIRA/ VALMIR (85985946718) | D11: ALARES | E11: IMPLANTAÇÃO | F11: CE | G11: =CONCATENATE(B11," - ",C11) -> XCE-05 - LEONARDO FERREIRA/ VALMIR (85985946718) | H11: FUSÃO
A12: 45 | B12: XCE-12 | C12: JOÃO PAULO/ LUCAS (85989820412) | D12: ALARES | E12: IMPLANTAÇÃO | F12: CE | G12: =CONCATENATE(B12," - ",C12) -> XCE-12 - JOÃO PAULO/ LUCAS (85989820412) | H12: FUSÃO
A13: 55 | B13: XPB-01 | C13: PABLO OLIVEIRA E AGNO SERGIO | D13: X-ON | E13: MANUTENÇÃO | F13: PB | G13: =CONCATENATE(B13," - ",C13) -> XPB-01 - PABLO OLIVEIRA E AGNO SERGIO | H13: FUSÃO
... A18: 61 | B18: XPB-04 | C18: WELLINGTON BRONZEADO E ISAAC | D18: X-ON | E18: MANUTENÇÃO | F18: PB | G18: =CONCATENATE(B18," - ",C18) -> XPB-04 - WELLINGTON BRONZEADO E ISAAC | H18: FUSÃO
A19: 05dea2e6 | B19: XRN-01 | C19: PAULO ROBERTO (84996063007) | D19: ALARES | E19: IMPLANTAÇÃO | F19: RN | G19: =CONCATENATE(B19," - ",C19) -> XRN-01 - PAULO ROBERTO (84996063007) | H19: FUSÃO
A20: 53ef62a7 | B20: XCE-08 | C20: DANIEL MELO | D20: ALARES | E20: IMPLANTAÇÃO | F20: CE | G20: =CONCATENATE(B20," - ",C20) -> XCE-08 - DANIEL MELO | H20: IMPLANTAÇÃO , FUSÃO
A21: 5aac2867 | B21: XCE-10 | C21: EVANILDO/ DELANO (85991198015) | D21: ALARES | E21: IMPLANTAÇÃO | F21: CE | G21: =CONCATENATE(B21," - ",C21) -> XCE-10 - EVANILDO/ DELANO (85991198015) | H21: FUSÃO
A22: 60db2b1b | B22: XCE-09 | C22: ALEF/ CAIKY (85998135803) | D22: ALARES | E22: IMPLANTAÇÃO | F22: CE | G22: =CONCATENATE(B22," - ",C22) -> XCE-09 - ALEF/ CAIKY (85998135803) | H22: FUSÃO
A23: 69e850a9 | B23: XCE-11 | C23: FRANCISCO/ WILL (85991442161) | D23: ALARES | E23: IMPLANTAÇÃO | F23: CE | G23: =CONCATENATE(B23," - ",C23) -> XCE-11 - FRANCISCO/ WILL (85991442161) | H23: FUSÃO
A24: 9ab51889 | B24: XCE-07 | C24: JOAQUIM GOMES/ ODAIL (85996525161) | D24: ALARES | E24: IMPLANTAÇÃO | F24: CE | G24: =CONCATENATE(B24," - ",C24) -> XCE-07 - JOAQUIM GOMES/ ODAIL (85996525161) | H24: FUSÃO
A25: a7a1ffee | B25: ALARES | C25: ALARES | D25: ALARES | E25: IMPLANTAÇÃO | F25: CE | G25: =CONCATENATE(B25," - ",C25) -> ALARES - ALARES | H25: IMPLANTAÇÃO
A26: d975757f | B26: XCE-03 | C26: FERNANDO/ MAURÍCIO (85982026260) | D26: ALARES | E26: IMPLANTAÇÃO | F26: CE | G26: =CONCATENATE(B26," - ",C26) -> XCE-03 - FERNANDO/ MAURÍCIO (85982026260) | H26: LANÇAMENTO
A27: 872208aa | B27: XRN-04 | C27: HÉLDER (84998410790) | D27: ALARES | E27: Implantação | F27: RN | G27: =CONCATENATE(B27," - ",C27) -> XRN-04 - HÉLDER (84998410790) | H27: IMPLANTAÇÃO
A28: 0611f994 | B28: XPRN-01 | C28: DEDA (84991662573) | D28: ALARES | E28: LANÇAMENTO | F28: RN | G28: =CONCATENATE(B28," - ",C28) -> XPRN-01 - DEDA (84991662573) | H28: IMPLANTAÇÃO
A29: 2cc0d5b5 | B29: XCE-14 | C29: YURY NEUTON (85996923320) | D29: ALARES | E29: IMPLANTAÇÃO | F29: CE | G29: =CONCATENATE(B29," - ",C29) -> XCE-14 - YURY NEUTON (85996923320) | H29: IMPLANTAÇÃO
A30: 65605b36 | B30: XCE-15 | C30: AMARO INSTALAÇÕES (85981396733) | D30: ALARES | E30: INPLANTAÇÃO | F30: CE | G30: =CONCATENATE(B30," - ",C30) -> XCE-15 - AMARO INSTALAÇÕES (85981396733) | H30: IMPLANTAÇÃO
A31: edd7d94a | B31: XPB-07 | C31: CARLOS EDUARDO (88997640024) | D31: ALARES | E31: INPLANTAÇÃO | F31: PB | G31: =CONCATENATE(B31," - ",C31) -> XPB-07 - CARLOS EDUARDO (88997640024)
A32: 5d3ad8f5 | B32: XCE-16 | C32: FERNANDO SOUZA (85996616671) | D32: ALARES | E32: IMPLANTAÇÃO | F32: CE | G32: =CONCATENATE(B32," - ",C32) -> XCE-16 - FERNANDO SOUZA (85996616671) | H32: IMPLANTAÇÃO

Sheet Giro
A1: F | B1: NUM | C1: Calendário | D1: Produção DIA | E1: Produção ACUMULADA | F1: GIRO | G1: =SUM(D3:D45) -> 0
B2: 1 | C2: 44942 | D2: =COUNTIFS(Os!I:I,$C2,Os!M:M,"Concluído") -> 0 | E2: =D2 -> 0 | F2: =E2/B2 -> 0
B3: 2 | C3: 44943 | D3: =COUNTIFS(Os!I:I,$C3,Os!M:M,"Concluído") -> 0 | E3: =D3+E2 -> 0 | F3: =E3/B3 -> 0
